Workbook
Name Level: 'Character Sheet'!$AZ$13

Sheet Home
B2: PF2E Autocalculating Character Sheet Exhanced v1.1
B4: By /u/AshenCombatant
B6: Make your own copy to edit here: | E6: For latest version, check out my reddit post:
B7: =HYPERLINK("https://docs.google.com/spreadsheets/d/1pzthCB-W3bPIQcDa4NM8RQG-VB-sOx90V-dj5Lt8Dg8/copy?usp=sharing","CLICK HERE") -> CLICK HERE | E7: You are viewing the latest version
B11: Colour Legend | E11: Tips
B12: Auto-calculated (useful) | C12: DO NOT EDIT THESE CELLS | E12: - Check out the setting at the top right to fade details
B13: Auto-calculated (less useful) | E13: - You can change the ability used for a calculation by changing the three-letter abbreviation above the box.
B14: User-provided (numbers) | C14: EDIT THESE CELLS
B15: User-provided (free-form) | E15: - If you have more than one proficiency selected (i.e. for TEML), the sheet will simply use the highest one.
E17: - You can use L (light) as the Bulk value for equipment.
B18: Credits | E18: - HIDE any sheets you are not using
B19: Creation | C19: Reddit user
B20: =HYPERLINK("https://docs.google.com/spreadsheets/d/1V6l7A0kaPkPUjNlwFEqziMnE5NWnCELZ42yW4ePbexE/edit#gid=757414001","Original PF1E AutoSheet") -> Original PF1E AutoSheet | C20: =HYPERLINK("https://www.reddit.com/user/darthmarth28","/u/darthmarth28") -> /u/darthmarth28 | E20: Author's Note
B21: =HYPERLINK("https://www.reddit.com/r/Pathfinder_RPG/comments/944tip/i_made_a_google_sheets_autosheet_for_2e_based_on/","PF2E Playtest AutoSheet") -> PF2E Playtest AutoSheet | C21: =HYPERLINK("https://www.reddit.com/user/galacticArtificer","/u/galacticArtificer") -> /u/galacticArtificer | E21: This character sheet is as up to date as Treasure Vault, and includes the formatting for spells and classes from the expansion, but with the inevitable addition of more content I have done what I can with adding a "Other" to the (hidden) Data tab, allowing quick changes for any homebrew or new classes that may be added. Good luck using this sheet, its as fool proof as I could make it.
B22: =HYPERLINK("http://knowdirectionpodcast.com/2019/08/perrams-landscape-character-sheet-for-pathfinder-second-edition/","PF2E Sheet Design") -> PF2E Sheet Design | C22: =HYPERLINK("https://www.reddit.com/user/perram","/u/perram") -> /u/perram
B23: =HYPERLINK("https://www.reddit.com/r/Pathfinder2e/comments/cpc3yz/pathfinder_2e_autosheet_on_google_docs/","PF2E AutoSheet (Color)") -> PF2E AutoSheet (Color) | C23: =HYPERLINK("https://www.reddit.com/user/FireandStone/","/u/FireandStone") -> /u/FireandStone
B24: =HYPERLINK("https://www.reddit.com/r/Pathfinder2e/comments/cqzg14/autocharacter_sheet_for_players_using_google/","PF2E AutoSheet (B/W)") -> PF2E AutoSheet (B/W) | C24: =HYPERLINK("https://www.reddit.com/user/selfconfessedcynic","/u/selfconfessedcynic") -> /u/selfconfessedcynic
B25: PF2E Simplified | C25: =HYPERLINK("https://www.reddit.com/user/scientificbruno/","/u/scientificbruno") -> /u/scientificbruno
B26: PF2E Simplified 2.0 | C26: =HYPERLINK("https://www.reddit.com/user/scientificbruno/","/u/scientificbruno") -> /u/scientificbruno
B27: Current Version | C27: /u/AshenCombatant

Sheet Character Sheet
Q2: Character Name | U2: Jeff | AM2: Ancestry | AQ2: Gnome | AX2: Heritage
AM4: Background | AX4: Size
Q6: Player | U6: Jerry | AM6: Class | AQ6: Druid | AX6: Key Ability | BB6: Wis
B7: Action/Activity Icon Legend
B8: 1, 2, or 3 actions | H8: Free | K8: Reaction | N8: Variable | Q8: Alignment | AB8: Deity | AM8: Experience | AU8: XP | AX8: Spellcasting Tradition | BB8: Primal
B11: PORTRAIT | L11: ABILITY SCORES | AA11: ARMOR CLASS | AS11: HIT POINTS | AZ11: Level | BD11: Hero Points
B12: >:D | N12: Score | P12: Modifier | U12: Score | W12: Modifier | AA12: AC | AD12: Dex | AF12: Prof | AH12: Item | AJ12: Shield | AM12: HP | AO12: Hard | AP12: BT | AQ12: Max | AS12: Current | AW12: Max
M13: STR | O13: 10 | P13: =MODIFIER(ROUNDDOWN((O13-10)/2,0)) -> +0 | T13: INT | V13: 10 | W13: =MODIFIER(ROUNDDOWN((V13-10)/2,0)) -> +0 | AA13: =10+AD13+AH13+AF13 -> 14 | AC13: = | AD13: =MIN(vlookup(AD12,Data!$B$14:$C$19,2,0), Inventory!$P$6) -> 0 | AE13: + | AF13: =SWITCH(Inventory!$B$8, AA15, if(AD17,8+Level,if(AC17,6+Level,if(AB17,4+Level,if(AA17,2+Level,0)))), AE15, if(AH17,8+Level,if(AG17,6+Level,if(AF17,4+Level,if(AE17,2+Level,0)))), AJ15, if(AM17,8+Level,if(AL17,6+Level,if(AK17,4+Level,if(AJ17,2+Level,0)))), AN15, if(AQ17,8+Level,if(AP17,6+Level,if(AO17,4+Level,if(AN17,2+Level,0))))) -> 3 | AG13: + | AH13: =Inventory!$M$6+Inventory!$M$8 -> 1 | AJ13: =MODIFIER(Inventory!$M$12) -> +1 | AO13: =Inventory!$S$12 -> 3 | AP13: =Inventory!$Y$12 -> 3 | AQ13: =Inventory!$V$12 -> 6 | AV13: / | AW13: =VLOOKUP($AQ$2,Data!B23:C33,2, FALSE) + (VLOOKUP($AQ$6,Data!B37:C58,2, FALSE) + VLOOKUP("Con", Data!$B$14:$C$19, 2, FALSE)) * $AZ$13 + $AW$15 -> 16 | AZ13: 1 | BD13: FALSE | BE13: FALSE | BF13: FALSE
AW14: Bonus HP
M15: DEX | O15: 10 | P15: =MODIFIER(ROUNDDOWN((O15-10)/2,0)) -> +0 | T15: WIS | V15: 10 | W15: =MODIFIER(ROUNDDOWN((V15-10)/2,0)) -> +0 | AA15: Unarmored | AE15: Light Armor | AJ15: Medium Armor | AN15: Heavy Armor | AW15: 0
AA16: T | AB16: E | AC16: M | AD16: L | AE16: T | AF16: E | AG16: M | AH16: L | AJ16: T | AK16: E | AL16: M | AM16: L | AN16: T | AO16: E | AP16: M | AQ16: L | AS16: Dying | AU16: Wounded | AW16: Temp HP | BA16: Settings
M17: CON | O17: 10 | P17: =MODIFIER(ROUNDDOWN((O17-10)/2,0)) -> +0 | T17: CHA | V17: 10 | W17: =MODIFIER(ROUNDDOWN((V17-10)/2,0)) -> +0 | AA17: TRUE | AB17: FALSE | AC17: FALSE | AD17: FALSE | AE17: TRUE | AF17: FALSE | AG17: FALSE | AH17: FALSE | AJ17: FALSE | AK17: FALSE | AL17: FALSE | AM17: FALSE | AN17: FALSE | AO17: FALSE | AP17: FALSE | AQ17: FALSE | AT17: /
BA18: FALSE | BB18: Untrained Improv.
L19: CLASS DC | AA19: SAVING THROWS | AS19: PERCEPTION
M20: Total | P20: Base | R20: =BB6 -> Wis | T20: Prof. | U20: T | V20: E | W20: M | X20: L | AF20: Total | AI20: Con | AK20: Prof. | AL20: T | AM20: E | AN20: M | AO20: L | AQ20: Item | AS20: Total | AV20: Wis | AX20: Item | BA20: FALSE | BB20: W. Specialization
M21: =P21+R21+T21 -> 13 | O21: = | P21: 10 | Q21: + | R21: =vlookup(R20,Data!$B$14:$C$19,2,0) -> 0 | S21: + | T21: =if(X21,8+$AZ$13,if(W21,6+$AZ$13,if(V21,4+$AZ$13,if(U21,2+$AZ$13,0)))) -> 3 | U21: TRUE | V21: FALSE | W21: FALSE | X21: FALSE | AA21: Fortitude | AF21: =MODIFIER(AI21+AK21+AQ21) -> +3 | AH21: = | AI21: =vlookup(AI20,Data!$B$14:$C$19,2,0) -> 0 | AJ21: + | AK21: =if(AO21,8+Level,if(AN21,6+Level,if(AM21,4+Level,if(AL21,2+Level,0)))) -> 3 | AL21: TRUE | AM21: FALSE | AN21: FALSE | AO21: FALSE | AP21: + | AQ21: 0 | AS21: =MODIFIER(AT23+AV21+AX21) -> +3 | AU21: = | AV21: =vlookup(AV20,Data!$B$14:$C$19,2,0) -> 0 | AW21: + | AX21: 0
AF22: Total | AI22: Dex | AK22: Prof. | AL22: T | AM22: E | AN22: M | AO22: L | AQ22: Item | AT22: Prof. | AU22: T | AV22: E | AW22: M | AX22: L | BA22: FALSE | BB22: Fade Calculations
L23: SPEED | AA23: Reflex | AF23: =MODIFIER(AI23+AK23+AQ23) -> +3 | AH23: = | AI23: =vlookup(AI22,Data!$B$14:$C$19,2,0) -> 0 | AJ23: + | AK23: =if(AO23,8+$AZ$13,if(AN23,6+$AZ$13,if(AM23,4+$AZ$13,if(AL23,2+$AZ$13,0)))) -> 3 | AL23: TRUE | AM23: FALSE | AN23: FALSE | AO23: FALSE | AP23: + | AQ23: 0 | AS23: + | AT23: =if(AX23,8+$AZ$13,if(AW23,6+$AZ$13,if(AV23,4+$AZ$13,if(AU23,2+$AZ$13,0)))) -> 3 | AU23: TRUE | AV23: FALSE | AW23: FALSE | AX23: FALSE
M24: Speed | P24: Base | R24: Penalties | T24: Movement Types & Notes | AF24: Total | AI24: Wis | AK24: Prof. | AL24: T | AM24: E | AN24: M | AO24: L | AQ24: Item | AS24: Notes
M25: =P25-R25 -> 25 | O25: = | P25: 25 | Q25: – | R25: =ABS(if(Inventory!$Y$6>$O$13,Inventory!$V$6,max(Inventory!$V$6-5,0))) + ABS(Inventory!$P$12) -> 0 | AA25: Will | AF25: =MODIFIER(AI25+AK25+AQ25) -> +3 | AH25: = | AI25: =vlookup(AI24,Data!$B$14:$C$19,2,0) -> 0 | AJ25: + | AK25: =if(AO25,8+$AZ$13,if(AN25,6+$AZ$13,if(AM25,4+$AZ$13,if(AL25,2+$AZ$13,0)))) -> 3 | AL25: TRUE | AM25: FALSE | AN25: FALSE | AO25: FALSE | AP25: + | AQ25: 0 | AZ25: LANGUAGES
AZ26: Common (Taldane), [Racial, +1 for each INT mod]
B27: WEAPON PROFICIENCIES | AA27: SPELL ATTACK ROLL AND DC
B28: Simple/Unarmed | G28: Martial | AB28: Attack | AE28: =IF(OR($BB$6 = "Int", $BB$6 = "Wis"), $BB$6, "Cha") -> Wis | AG28: Prof. | AH28: T | AI28: E | AJ28: M | AK28: L | AM28: Item | AP28: DC | AS28: Base | AU28: =AE28 -> Wis | AW28: Prof.
B29: TRUE | C29: FALSE | D29: FALSE | E29: FALSE | G29: FALSE | H29: FALSE | I29: FALSE | J29: FALSE | L29: FALSE | M29: FALSE | N29: FALSE | O29: FALSE | Q29: FALSE | R29: FALSE | S29: FALSE | T29: FALSE | V29: FALSE | W29: FALSE | X29: FALSE | Y29: FALSE | AB29: =MODIFIER(AE29+AG29+AM29) -> +0 | AD29: = | AE29: =vlookup(AE28,Data!$B$14:$C$19,2,0) -> 0 | AF29: + | AG29: =if(AK29,8+$AZ$13,if(AJ29,6+$AZ$13,if(AI29,4+$AZ$13,if(AH29,2+$AZ$13,0)))) -> 0 | AH29: FALSE | AI29: FALSE | AJ29: FALSE | AK29: FALSE | AL29: + | AM29: 0 | AP29: =AS29+AU29+AW29 -> 10 | AR29: = | AS29: 10 | AT29: + | AU29: =vlookup(AU28,Data!$B$14:$C$19,2,0) -> 0 | AV29: + | AW29: =AG29 -> 0
B30: T | C30: E | D30: M | E30: L | G30: T | H30: E | I30: M | J30: L | L30: T | M30: E | N30: M | O30: L | Q30: T | R30: E | S30: M | T30: L | V30: T | W30: E | X30: M | Y30: L
B31: MELEE STRIKES | AA31: RANGED STRIKES
B32: Weapon | N32: Attack | Q32: =IF(K35,"Dex","Str") -> Str | S32: Prof. | T32: T | U32: E | V32: M | W32: L | Y32: Item | AA32: Weapon | AM32: Attack | AP32: Dex | AR32: Prof. | AS32: T | AT32: E | AU32: M | AV32: L | AX32: Item
N33: =MODIFIER(Q33+S33+Y33) -> +0 | P33: = | Q33: =vlookup(Q32,Data!$B$14:$C$19,2,0) -> 0 | R33: + | S33: =if(W33,8+$AZ$13,if(V33,6+$AZ$13,if(U33,4+$AZ$13,if(T33,2+$AZ$13,0)))) -> 0 | T33: FALSE | U33: FALSE | V33: FALSE | W33: FALSE | X33: + | Y33: 0 | AM33: =MODIFIER(AP33+AR33+AX33) -> +0 | AO33: = | AP33: =vlookup(AP32,Data!$B$14:$C$19,2,0) -> 0 | AQ33: + | AR33: =if(AV33,8+$AZ$13,if(AU33,6+$AZ$13,if(AT33,4+$AZ$13,if(AS33,2+$AZ$13,0)))) -> 0 | AS33: FALSE | AT33: FALSE | AU33: FALSE | AV33: FALSE | AW33: + | AX33: 0 | AZ33: STANDARD ACTIONS
K35: FALSE | L35: FALSE | N35: =MODIFIER(Q33+S33+Y33-ABS(Q35)) -> –5 | O35: =MODIFIER(Q33+S33+Y33-2*ABS(Q35)) -> –10 | Q35: =IF(L35,-4,-5) -> -5 | V35: + | W35: =vlookup(W36,Data!$B$14:$C$19,2,0) -> 0 | X35: + | Y35: =if($BA$20, if(W33,4, if(V33,3 ,if(U33,2, 0))), 0) -> 0 | AK35: FALSE | AM35: =MODIFIER(AP33+AR33+AX33-ABS(AP35)) -> –5 | AN35: =MODIFIER(AP33+AR33+AX33-2*ABS(AP35)) -> –10 | AP35: =IF(AK35,-4,-5) -> -5 | AU35: + | AV35: 0 | AW35: + | AX35: =if($BA$20, if(AV33,4, if(AU33,3 ,if(AT33,2, 0))), 0) -> 0 | AZ35: Stride (Movement)
B36: Traits | K36: Fin. | L36: Agile | N36: Additional | Q36: MAP | S36: Damage | W36: Str | Y36: W.Spec | AA36: Traits | AG36: Reload | AI36: Range | AK36: Agile | AM36: Additional | AP36: MAP | AR36: Damage | AV36: Misc. | AX36: W.Spec
AZ37: Step (5ft, no reactions)
B38: Weapon | N38: Attack | Q38: =IF(K41,"Dex","Str") -> Str | S38: Prof. | T38: T | U38: E | V38: M | W38: L | Y38: Item | AA38: Weapon | AM38: Attack | AP38: Dex | AR38: Prof. | AS38: T | AT38: E | AU38: M | AV38: L | AX38: Item
N39: =MODIFIER(Q39+S39+Y39) -> +0 | P39: = | Q39: =vlookup(Q38,Data!$B$14:$C$19,2,0) -> 0 | R39: + | S39: =if(W39,8+$AZ$13,if(V39,6+$AZ$13,if(U39,4+$AZ$13,if(T39,2+$AZ$13,0)))) -> 0 | T39: FALSE | U39: FALSE | V39: FALSE | W39: FALSE | X39: + | Y39: 0 | AM39: =MODIFIER(AP39+AR39+AX39) -> +0 | AO39: = | AP39: =vlookup(AP38,Data!$B$14:$C$19,2,0) -> 0 | AQ39: + | AR39: =if(AV39,8+$AZ$13,if(AU39,6+$AZ$13,if(AT39,4+$AZ$13,if(AS39,2+$AZ$13,0)))) -> 0 | AS39: FALSE | AT39: FALSE | AU39: FALSE | AV39: FALSE | AW39: + | AX39: 0 | AZ39: Strike (Attack)
K41: FALSE | L41: FALSE | N41: =MODIFIER(Q39+S39+Y39-ABS(Q41)) -> –5 | O41: =MODIFIER(Q39+S39+Y39-2*ABS(Q41)) -> –10 | Q41: =IF(L41,-4,-5) -> -5 | V41: + | W41: =vlookup(W42,Data!$B$14:$C$19,2,0) -> 0 | X41: + | Y41: =if($BA$20, if(W39,4, if(V39,3 ,if(U39,2, 0))), 0) -> 0 | AK41: FALSE | AM41: =MODIFIER(AP39+AR39+AX39-ABS(AP41)) -> –5 | AN41: =MODIFIER(AP39+AR39+AX39-2*ABS(AP41)) -> –10 | AP41: =IF(AK41,-4,-5) -> -5 | AU41: + | AV41: 0 | AW41: + | AX41: =if($BA$20, if(AV39,4, if(AU39,3 ,if(AT39,2, 0))), 0) -> 0 | AZ41: Cast a (Standard) Spell
B42: Traits | K42: Fin. | L42: Agile | N42: Additional | Q42: MAP | S42: Damage | W42: Str | Y42: W.Spec | AA42: Traits | AG42: Reload | AI42: Range | AK42: Agile | AM42: Additional | AP42: MAP | AR42: Damage | AV42: Misc. | AX42: W.Spec
AZ43: Raise Shield (AC bonus)
B44: Weapon | N44: Attack | Q44: =IF(K47,"Dex","Str") -> Str | S44: Prof. | T44: T | U44: E | V44: M | W44: L | Y44: Item | AA44: Weapon | AM44: Attack | AP44: Dex | AR44: Prof. | AS44: T | AT44: E | AU44: M | AV44: L | AX44: Item
N45: =MODIFIER(Q45+S45+Y45) -> +0 | P45: = | Q45: =vlookup(Q44,Data!$B$14:$C$19,2,0) -> 0 | R45: + | S45: =if(W45,8+$AZ$13,if(V45,6+$AZ$13,if(U45,4+$AZ$13,if(T45,2+$AZ$13,0)))) -> 0 | T45: FALSE | U45: FALSE | V45: FALSE | W45: FALSE | X45: + | Y45: 0 | AM45: =MODIFIER(AP45+AR45+AX45) -> +0 | AO45: = | AP45: =vlookup(AP44,Data!$B$14:$C$19,2,0) -> 0 | AQ45: + | AR45: =if(AV45,8+$AZ$13,if(AU45,6+$AZ$13,if(AT45,4+$AZ$13,if(AS45,2+$AZ$13,0)))) -> 0 | AS45: FALSE | AT45: FALSE | AU45: FALSE | AV45: FALSE | AW45: + | AX45: 0 | AZ45: Interact
K47: FALSE | L47: FALSE | N47: =MODIFIER(Q45+S45+Y45-ABS(Q47)) -> –5 | O47: =MODIFIER(Q45+S45+Y45-2*ABS(Q47)) -> –10 | Q47: =IF(L47,-4,-5) -> -5 | V47: + | W47: =vlookup(W48,Data!$B$14:$C$19,2,0) -> 0 | X47: + | Y47: =if($BA$20, if(W45,4, if(V45,3 ,if(U45,2, 0))), 0) -> 0 | AK47: FALSE | AM47: =MODIFIER(AP45+AR45+AX45-ABS(AP47)) -> –5 | AN47: =MODIFIER(AP45+AR45+AX45-2*ABS(AP47)) -> –10 | AP47: =IF(AK47,-4,-5) -> -5 | AU47: + | AV47: 0 | AW47: + | AX47: =if($BA$20, if(AV45,4, if(AU45,3 ,if(AT45,2, 0))), 0) -> 0 | AZ47: Delay (Hold Turn)
B48: Traits | K48: Fin. | L48: Agile | N48: Additional | Q48: MAP | S48: Damage | W48: Str | Y48: W.Spec | AA48: Traits | AG48: Reload | AI48: Range | AK48: Agile | AM48: Additional | AP48: MAP | AR48: Damage | AV48: Misc. | AX48: W.Spec
...

Sheet Abilities
A1: ABILITIES
B3: SKILLS
H4: Total | K4: Dex | M4: Prof. | N4: T | O4: E | P4: M | Q4: L | S4: Item | U4: Armor | W4: Feats | Y4: Feats listed | AM4: Item Being Used | AY4: FALSE | AZ4: Fade Calculations
C5: Acrobatics | H5: =MODIFIER(K5+M5+S5-U5+W5) -> +0 | J5: = | K5: =vlookup(K4,Data!$B$14:$C$19,2,0) -> 0 | L5: + | M5: =if(Q5,8+Level,if(P5,6+Level,if(O5,4+Level,if(N5,2+Level,IF('Character Sheet'!$BA$18,IF(Level>= 7, Level, ROUNDDOWN(Level/2,0)),0))))) -> 0 | N5: FALSE | O5: FALSE | P5: FALSE | Q5: FALSE | R5: + | S5: 0 | T5: – | U5: =ABS(if(Inventory!$Y$6>'Character Sheet'!$O$13,Inventory!$S$6,0)) -> 0 | V5: + | W5: 0
H6: Total | K6: Int | M6: Prof. | N6: T | O6: E | P6: M | Q6: L | S6: Item | W6: Feats | Y6: Feats listed | AM6: Item Being Used
C7: Arcana | H7: =MODIFIER(K7+M7+S7+W7) -> +0 | J7: = | K7: =vlookup(K6,Data!$B$14:$C$19,2,0) -> 0 | L7: + | M7: =if(Q7,8+Level,if(P7,6+Level,if(O7,4+Level,if(N7,2+Level,IF('Character Sheet'!$BA$18,IF(Level>= 7, Level, ROUNDDOWN(Level/2,0)),0))))) -> 0 | N7: FALSE | O7: FALSE | P7: FALSE | Q7: FALSE | R7: + | S7: 0 | U7: + | W7: 0 | AX7: SKILLS
H8: Total | K8: Str | M8: Prof. | N8: T | O8: E | P8: M | Q8: L | S8: Item | U8: Armor | W8: Feats | Y8: Feats listed | AM8: Item Being Used | AX8: 1st lv: [Class Bonus] + [Int Mod] for starting skills, each with a max of trained. On standard classes you gain more skill proficencies every other level 3rd lv: You can now put points into Expert ranked skills (if you are trained) 7th lv: You can now become a Master in a skill 15th lv: Legendary skill proficiencies are possible
C9: Athletics | H9: =MODIFIER(K9+M9+S9-U9+W9) -> +0 | J9: = | K9: =vlookup(K8,Data!$B$14:$C$19,2,0) -> 0 | L9: + | M9: =if(Q9,8+Level,if(P9,6+Level,if(O9,4+Level,if(N9,2+Level,IF('Character Sheet'!$BA$18,IF(Level>= 7, Level, ROUNDDOWN(Level/2,0)),0))))) -> 0 | N9: FALSE | O9: FALSE | P9: FALSE | Q9: FALSE | R9: + | S9: 0 | T9: – | U9: =ABS(if(Inventory!$Y$6>'Character Sheet'!$O$13,Inventory!$S$6,0)) -> 0 | V9: + | W9: 0
H10: Total | K10: Int | M10: Prof. | N10: T | O10: E | P10: M | Q10: L | S10: Item | W10: Feats | Y10: Feats listed | AM10: Item Being Used
C11: Crafting | H11: =MODIFIER(K11+M11+S11+W11) -> +0 | J11: = | K11: =vlookup(K10,Data!$B$14:$C$19,2,0) -> 0 | L11: + | M11: =if(Q11,8+Level,if(P11,6+Level,if(O11,4+Level,if(N11,2+Level,IF('Character Sheet'!$BA$18,IF(Level>= 7, Level, ROUNDDOWN(Level/2,0)),0))))) -> 0 | N11: FALSE | O11: FALSE | P11: FALSE | Q11: FALSE | R11: + | S11: 0 | U11: + | W11: 0
H12: Total | K12: Cha | M12: Prof. | N12: T | O12: E | P12: M | Q12: L | S12: Item | W12: Feats | Y12: Feats listed | AM12: Item Being Used
C13: Deception | H13: =MODIFIER(K13+M13+S13+W13) -> +0 | J13: = | K13: =vlookup(K12,Data!$B$14:$C$19,2,0) -> 0 | L13: + | M13: =if(Q13,8+Level,if(P13,6+Level,if(O13,4+Level,if(N13,2+Level,IF('Character Sheet'!$BA$18,IF(Level>= 7, Level, ROUNDDOWN(Level/2,0)),0))))) -> 0 | N13: FALSE | O13: FALSE | P13: FALSE | Q13: FALSE | R13: + | S13: 0 | U13: + | W13: 0
H14: Total | K14: Cha | M14: Prof. | N14: T | O14: E | P14: M | Q14: L | S14: Item | W14: Feats | Y14: Feats listed | AM14: Item Being Used
C15: Diplomacy | H15: =MODIFIER(K15+M15+S15+W15) -> +0 | J15: = | K15: =vlookup(K14,Data!$B$14:$C$19,2,0) -> 0 | L15: + | M15: =if(Q15,8+Level,if(P15,6+Level,if(O15,4+Level,if(N15,2+Level,IF('Character Sheet'!$BA$18,IF(Level>= 7, Level, ROUNDDOWN(Level/2,0)),0))))) -> 0 | N15: FALSE | O15: FALSE | P15: FALSE | Q15: FALSE | R15: + | S15: 0 | U15: + | W15: 0
H16: Total | K16: Cha | M16: Prof. | N16: T | O16: E | P16: M | Q16: L | S16: Item | W16: Feats | Y16: Feats listed | AM16: Item Being Used
C17: Intimidation | H17: =MODIFIER(K17+M17+S17+W17) -> +0 | J17: = | K17: =vlookup(K16,Data!$B$14:$C$19,2,0) -> 0 | L17: + | M17: =if(Q17,8+Level,if(P17,6+Level,if(O17,4+Level,if(N17,2+Level,IF('Character Sheet'!$BA$18,IF(Level>= 7, Level, ROUNDDOWN(Level/2,0)),0))))) -> 0 | N17: FALSE | O17: FALSE | P17: FALSE | Q17: FALSE | R17: + | S17: 0 | U17: + | W17: 0
H18: Total | K18: Int | M18: Prof. | N18: T | O18: E | P18: M | Q18: L | S18: Item | W18: Feats | Y18: Feats listed | AM18: Item Being Used
F19: Lore | H19: =MODIFIER(K19+M19+S19+W19) -> +0 | J19: = | K19: =vlookup(K18,Data!$B$14:$C$19,2,0) -> 0 | L19: + | M19: =if(Q19,8+Level,if(P19,6+Level,if(O19,4+Level,if(N19,2+Level,IF('Character Sheet'!$BA$18,IF(Level>= 7, Level, ROUNDDOWN(Level/2,0)),0))))) -> 0 | N19: FALSE | O19: FALSE | P19: FALSE | Q19: FALSE | R19: + | S19: 0 | U19: + | W19: 0
H20: Total | K20: Int | M20: Prof. | N20: T | O20: E | P20: M | Q20: L | S20: Item | W20: Feats | Y20: Feats listed | AM20: Item Being Used
F21: Lore | H21: =MODIFIER(K21+M21+S21+W21) -> +0 | J21: = | K21: =vlookup(K20,Data!$B$14:$C$19,2,0) -> 0 | L21: + | M21: =if(Q21,8+Level,if(P21,6+Level,if(O21,4+Level,if(N21,2+Level,IF('Character Sheet'!$BA$18,IF(Level>= 7, Level, ROUNDDOWN(Level/2,0)),0))))) -> 0 | N21: FALSE | O21: FALSE | P21: FALSE | Q21: FALSE | R21: + | S21: 0 | U21: + | W21: 0 | AX21: SIMPLE DC
H22: Total | K22: Int | M22: Prof. | N22: T | O22: E | P22: M | Q22: L | S22: Item | W22: Feats | Y22: Feats listed | AM22: Item Being Used
F23: Lore | H23: =MODIFIER(K23+M23+S23+W23) -> +0 | J23: = | K23: =vlookup(K22,Data!$B$14:$C$19,2,0) -> 0 | L23: + | M23: =if(Q23,8+Level,if(P23,6+Level,if(O23,4+Level,if(N23,2+Level,IF('Character Sheet'!$BA$18,IF(Level>= 7, Level, ROUNDDOWN(Level/2,0)),0))))) -> 0 | N23: FALSE | O23: FALSE | P23: FALSE | Q23: FALSE | R23: + | S23: 0 | U23: + | W23: 0
H24: Total | K24: Int | M24: Prof. | N24: T | O24: E | P24: M | Q24: L | S24: Item | W24: Feats | Y24: Feats listed | AM24: Item Being Used
F25: Lore | H25: =MODIFIER(K25+M25+S25+W25) -> +0 | J25: = | K25: =vlookup(K24,Data!$B$14:$C$19,2,0) -> 0 | L25: + | M25: =if(Q25,8+Level,if(P25,6+Level,if(O25,4+Level,if(N25,2+Level,IF('Character Sheet'!$BA$18,IF(Level>= 7, Level, ROUNDDOWN(Level/2,0)),0))))) -> 0 | N25: FALSE | O25: FALSE | P25: FALSE | Q25: FALSE | R25: + | S25: 0 | U25: + | W25: 0
H26: Total | K26: Wis | M26: Prof. | N26: T | O26: E | P26: M | Q26: L | S26: Item | W26: Feats | Y26: Feats listed | AM26: Item Being Used
C27: Medicine | H27: =MODIFIER(K27+M27+S27+W27) -> +0 | J27: = | K27: =vlookup(K26,Data!$B$14:$C$19,2,0) -> 0 | L27: + | M27: =if(Q27,8+Level,if(P27,6+Level,if(O27,4+Level,if(N27,2+Level,IF('Character Sheet'!$BA$18,IF(Level>= 7, Level, ROUNDDOWN(Level/2,0)),0))))) -> 0 | N27: FALSE | O27: FALSE | P27: FALSE | Q27: FALSE | R27: + | S27: 0 | U27: + | W27: 0
H28: Total | K28: Wis | M28: Prof. | N28: T | O28: E | P28: M | Q28: L | S28: Item | W28: Feats | Y28: Feats listed | AM28: Item Being Used
C29: Nature | H29: =MODIFIER(K29+M29+S29+W29) -> +0 | J29: = | K29: =vlookup(K28,Data!$B$14:$C$19,2,0) -> 0 | L29: + | M29: =if(Q29,8+Level,if(P29,6+Level,if(O29,4+Level,if(N29,2+Level,IF('Character Sheet'!$BA$18,IF(Level>= 7, Level, ROUNDDOWN(Level/2,0)),0))))) -> 0 | N29: FALSE | O29: FALSE | P29: FALSE | Q29: FALSE | R29: + | S29: 0 | U29: + | W29: 0
H30: Total | K30: Int | M30: Prof. | N30: T | O30: E | P30: M | Q30: L | S30: Item | W30: Feats | Y30: Feats listed | AM30: Item Being Used
C31: Occultism | H31: =MODIFIER(K31+M31+S31+W31) -> +0 | J31: = | K31: =vlookup(K30,Data!$B$14:$C$19,2,0) -> 0 | L31: + | M31: =if(Q31,8+Level,if(P31,6+Level,if(O31,4+Level,if(N31,2+Level,IF('Character Sheet'!$BA$18,IF(Level>= 7, Level, ROUNDDOWN(Level/2,0)),0))))) -> 0 | N31: FALSE | O31: FALSE | P31: FALSE | Q31: FALSE | R31: + | S31: 0 | U31: + | W31: 0
H32: Total | K32: Cha | M32: Prof. | N32: T | O32: E | P32: M | Q32: L | S32: Item | W32: Feats | Y32: Feats listed | AM32: Item Being Used
C33: Performance | H33: =MODIFIER(K33+M33+S33+W33) -> +0 | J33: = | K33: =vlookup(K32,Data!$B$14:$C$19,2,0) -> 0 | L33: + | M33: =if(Q33,8+Level,if(P33,6+Level,if(O33,4+Level,if(N33,2+Level,IF('Character Sheet'!$BA$18,IF(Level>= 7, Level, ROUNDDOWN(Level/2,0)),0))))) -> 0 | N33: FALSE | O33: FALSE | P33: FALSE | Q33: FALSE | R33: + | S33: 0 | U33: + | W33: 0 | AX33: SITUATIONAL
H34: Total | K34: Wis | M34: Prof. | N34: T | O34: E | P34: M | Q34: L | S34: Item | W34: Feats | Y34: Feats listed | AM34: Item Being Used | AX34: random effects to use as needed
C35: Religion | H35: =MODIFIER(K35+M35+S35+W35) -> +0 | J35: = | K35: =vlookup(K34,Data!$B$14:$C$19,2,0) -> 0 | L35: + | M35: =if(Q35,8+Level,if(P35,6+Level,if(O35,4+Level,if(N35,2+Level,IF('Character Sheet'!$BA$18,IF(Level>= 7, Level, ROUNDDOWN(Level/2,0)),0))))) -> 0 | N35: FALSE | O35: FALSE | P35: FALSE | Q35: FALSE | R35: + | S35: 0 | U35: + | W35: 0
H36: Total | K36: Int | M36: Prof. | N36: T | O36: E | P36: M | Q36: L | S36: Item | W36: Feats | Y36: Feats listed | AM36: Item Being Used
C37: Society | H37: =MODIFIER(K37+M37+S37+W37) -> +0 | J37: = | K37: =vlookup(K36,Data!$B$14:$C$19,2,0) -> 0 | L37: + | M37: =if(Q37,8+Level,if(P37,6+Level,if(O37,4+Level,if(N37,2+Level,IF('Character Sheet'!$BA$18,IF(Level>= 7, Level, ROUNDDOWN(Level/2,0)),0))))) -> 0 | N37: FALSE | O37: FALSE | P37: FALSE | Q37: FALSE | R37: + | S37: 0 | U37: + | W37: 0
H38: Total | K38: Dex | M38: Prof. | N38: T | O38: E | P38: M | Q38: L | S38: Item | U38: Armor | W38: Feats | Y38: Feats listed | AM38: Item Being Used
C39: Stealth | H39: =MODIFIER(K39+M39+S39-U39+W39) -> +0 | J39: = | K39: =vlookup(K38,Data!$B$14:$C$19,2,0) -> 0 | L39: + | M39: =if(Q39,8+Level,if(P39,6+Level,if(O39,4+Level,if(N39,2+Level,IF('Character Sheet'!$BA$18,IF(Level>= 7, Level, ROUNDDOWN(Level/2,0)),0))))) -> 0 | N39: FALSE | O39: FALSE | P39: FALSE | Q39: FALSE | R39: + | S39: 0 | T39: – | U39: =ABS(if(Inventory!$Y$6>'Character Sheet'!$O$13,Inventory!$S$6,0)) -> 0 | V39: + | W39: 0
H40: Total | K40: Wis | M40: Prof. | N40: T | O40: E | P40: M | Q40: L | S40: Item | W40: Feats | Y40: Feats listed | AM40: Item Being Used
C41: Survival | H41: =MODIFIER(K41+M41+S41+W41) -> +0 | J41: = | K41: =vlookup(K40,Data!$B$14:$C$19,2,0) -> 0 | L41: + | M41: =if(Q41,8+Level,if(P41,6+Level,if(O41,4+Level,if(N41,2+Level,IF('Character Sheet'!$BA$18,IF(Level>= 7, Level, ROUNDDOWN(Level/2,0)),0))))) -> 0 | N41: FALSE | O41: FALSE | P41: FALSE | Q41: FALSE | R41: + | S41: 0 | U41: + | W41: 0
...

Sheet Inventory
B2: INVENTORY
B4: ARMOR | AG4: OTHER INVENTORY | BH4: OTHER OTHER INVENTORY | CI4: Coin Bulk
B5: Item | M5: AC | P5: Dex Cap | S5: Check Pen | V5: Speed Pen | Y5: Str Req | AB5: Bulk | AE5: Invest | AG5: Weapon 1 | BA5: Qty | BC5: Bulk | BE5: Total Bulk | BH5: Adventurer's pack (max. 4 bulk, minus 2 bulk) | CF5: Total Bulk | CJ5: Standard Rules
B6: Padded armor | M6: 1 | P6: 3 | S6: 0 | V6: 0 | Y6: 10 | AB6: L | AE6: 0 | BB6: x | BC6: 1 | BD6: = | BE6: =IF(BC6="",0,IF(BA6="", CALCBULK(BC6), BA6*CALCBULK(BC6))) -> 1 | CF6: =MAX(SUM(CF8:CG38) - 2, 0) -> 0 | CJ6: 0
B7: Group | M7: Runes | P7: Armor Traits | AG7: Weapon 2 | BA7: Qty | BC7: Bulk | BE7: Total Bulk | BI7: Backpack, Bedroll, Belt pouch (2), Chalk (10), Flint/steel, Rope (50 ft), Rations (2 weeks), Soap, Torch (5), Waterskin | CB7: Qty | CD7: Bulk | CF7: Total Bulk | CJ7: Exact Wieght
B8: Light Armor | M8: 0 | BB8: x | BC8: 1 | BD8: = | BE8: =IF(BC8="",0,IF(BA8="", CALCBULK(BC8), BA8*CALCBULK(BC8))) -> 1 | CC8: x | CD8: 1 | CE8: = | CF8: =IF(CD8="",0,IF(CB8="", CALCBULK(CD8), CB8*CALCBULK(CD8))) -> 1 | CJ8: 0
AG9: Healer's/Alchemist's/Thieves' Tool | BA9: Qty | BC9: Bulk | BE9: Total Bulk | BI9: Climbing/Repair/Disguise/Snare kit | CB9: Qty | CD9: Bulk | CF9: Total Bulk | CJ9: Resulting Bulk
B10: SHIELD | BB10: x | BC10: 1 | BD10: = | BE10: =IF(BC10="",0,IF(BA10="", CALCBULK(BC10), BA10*CALCBULK(BC10))) -> 1 | CC10: x | CD10: 1 | CE10: = | CF10: =IF(CD10="",0,IF(CB10="", CALCBULK(CD10), CB10*CALCBULK(CD10))) -> 1 | CI10: =IFS(CJ8,(Sum(X16,X18,AB16,AB18)/1000),CJ6=1,ROUNDDOWN(SUM(X16,X18,AB16,AB18)/1000,0),CJ6=0, "0") -> 0
B11: Item | M11: AC | P11: Speed Pen | S11: Hardness | V11: Max HP | Y11: BT | AB11: Bulk | AE11: Invest | BA11: Qty | BC11: Bulk | BE11: Total Bulk | CB11: Qty | CD11: Bulk | CF11: Total Bulk
B12: Buckler | M12: 1 | P12: 0 | S12: 3 | V12: 6 | Y12: 3 | AB12: L | AE12: 0 | BB12: x | BC12: 0 | BD12: = | BE12: =IF(BC12="",0,IF(BA12="", CALCBULK(BC12), BA12*CALCBULK(BC12))) -> 0 | CC12: x | CD12: 0 | CE12: = | CF12: =IF(CD12="",0,IF(CB12="", CALCBULK(CD12), CB12*CALCBULK(CD12))) -> 0
BA13: Qty | BC13: Bulk | BE13: Total Bulk | CB13: Qty | CD13: Bulk | CF13: Total Bulk
B14: INVENTORY | BB14: x | BD14: = | BE14: =IF(BC14="",0,IF(BA14="", CALCBULK(BC14), BA14*CALCBULK(BC14))) -> 0 | CC14: x | CD14: 0 | CE14: = | CF14: =IF(CD14="",0,IF(CB14="", CALCBULK(CD14), CB14*CALCBULK(CD14))) -> 0
B15: Current Bulk | E15: Exact Bulk | I15: Invested | M15: Max | O15: Notes | X15: CP | AB15: GP | BA15: Qty | BC15: Bulk | BE15: Total Bulk | CB15: Qty | CD15: Bulk | CF15: Total Bulk
B16: =ROUNDDOWN(E16,0) -> 3 | E16: =SUM(CALCBULK(AB6,AB12),BE6:BE40,CF6,BE50)+Sum(AE26:AE54)+(IF(CC40,CF40))+CI10 -> 3.2 | I16: =SUM($I$26:$I$54,AE12,AE6) -> 1 | L16: / | M16: 10 | X16: 0 | AB16: 15 | BB16: x | BD16: = | BE16: =IF(BC16="",0,IF(BA16="", CALCBULK(BC16), BA16*CALCBULK(BC16))) -> 0 | CC16: x | CD16: 0 | CE16: = | CF16: =IF(CD16="",0,IF(CB16="", CALCBULK(CD16), CB16*CALCBULK(CD16))) -> 0
B17: Enc | D17: Max | F17: Base | I17: Str | K17: Bonus | M17: Item | X17: SP | AB17: PP | BA17: Qty | BC17: Bulk | BE17: Total Bulk | CB17: Qty | CD17: Bulk | CF17: Total Bulk
B18: =5+$I$18+$K$18+$M$18 -> 5 | C18: / | D18: =10+$I$18+$K$18+$M$18 -> 10 | E18: = | F18: 5 / 10 | H18: + | I18: =vlookup(I17,Data!$B$14:$C$19,2,0) -> 0 | J18: + | K18: 0 | L18: + | M18: 0 | X18: 0 | AB18: 0 | BB18: x | BD18: = | BE18: =IF(BC18="",0,IF(BA18="", CALCBULK(BC18), BA18*CALCBULK(BC18))) -> 0 | CC18: x | CD18: 0 | CE18: = | CF18: =IF(CD18="",0,IF(CB18="", CALCBULK(CD18), CB18*CALCBULK(CD18))) -> 0
BA19: Qty | BC19: Bulk | BE19: Total Bulk | CB19: Qty | CD19: Bulk | CF19: Total Bulk
B20: AMMUNITION | BB20: x | BD20: = | BE20: =IF(BC20="",0,IF(BA20="", CALCBULK(BC20), BA20*CALCBULK(BC20))) -> 0 | CC20: x | CD20: 0 | CE20: = | CF20: =IF(CD20="",0,IF(CB20="", CALCBULK(CD20), CB20*CALCBULK(CD20))) -> 0
B21: Arrows | F21: Frost Arrow | J21: Type 3 | N21: Type 4 | T21: Type 5 | Z21: Type 6 | AD21: Bulk | BA21: Qty | BC21: Bulk | BE21: Total Bulk | CB21: Qty | CD21: Bulk | CF21: Total Bulk
B22: 0 | F22: 0 | J22: 0 | N22: 0 | T22: 0 | Z22: 0 | AD22: =Sum(B22,F22,J22,N22,T22,Z22)*0.01 -> 0 | BB22: x | BD22: = | BE22: =IF(BC22="",0,IF(BA22="", CALCBULK(BC22), BA22*CALCBULK(BC22))) -> 0 | CC22: x | CD22: 0 | CE22: = | CF22: =IF(CD22="",0,IF(CB22="", CALCBULK(CD22), CB22*CALCBULK(CD22))) -> 0
BA23: Qty | BC23: Bulk | BE23: Total Bulk | CB23: Qty | CD23: Bulk | CF23: Total Bulk
B24: MAGIC ITEMS | BB24: x | BD24: = | BE24: =IF(BC24="",0,IF(BA24="", CALCBULK(BC24), BA24*CALCBULK(BC24))) -> 0 | CC24: x | CD24: 0 | CE24: = | CF24: =IF(CD24="",0,IF(CB24="", CALCBULK(CD24), CB24*CALCBULK(CD24))) -> 0
B25: Name | I25: Invest | L25: Description | AE25: Bulk | BA25: Qty | BC25: Bulk | BE25: Total Bulk | CB25: Qty | CD25: Bulk | CF25: Total Bulk
B26: Stick of Division | I26: 1 | K26: The most stick-like of sticks, has the powers of multiplication | AE26: 0 | BB26: x | BD26: = | BE26: =IF(BC26="",0,IF(BA26="", CALCBULK(BC26), BA26*CALCBULK(BC26))) -> 0 | CC26: x | CD26: 0 | CE26: = | CF26: =IF(CD26="",0,IF(CB26="", CALCBULK(CD26), CB26*CALCBULK(CD26))) -> 0
I27: 0 | AE27: Bulk | BA27: Qty | BC27: Bulk | BE27: Total Bulk | CB27: Qty | CD27: Bulk | CF27: Total Bulk
AE28: 0 | BB28: x | BD28: = | BE28: =IF(BC28="",0,IF(BA28="", CALCBULK(BC28), BA28*CALCBULK(BC28))) -> 0 | CC28: x | CD28: 0 | CE28: = | CF28: =IF(CD28="",0,IF(CB28="", CALCBULK(CD28), CB28*CALCBULK(CD28))) -> 0
I29: 0 | AE29: Bulk | BA29: Qty | BC29: Bulk | BE29: Total Bulk | CB29: Qty | CD29: Bulk | CF29: Total Bulk
BB30: x | BD30: = | BE30: =IF(BC30="",0,IF(BA30="", CALCBULK(BC30), BA30*CALCBULK(BC30))) -> 0 | CC30: x | CD30: 0 | CE30: = | CF30: =IF(CD30="",0,IF(CB30="", CALCBULK(CD30), CB30*CALCBULK(CD30))) -> 0
I31: 0 | AE31: Bulk | BA31: Qty | BC31: Bulk | BE31: Total Bulk | CB31: Qty | CD31: Bulk | CF31: Total Bulk
BB32: x | BD32: = | BE32: =IF(BC32="",0,IF(BA32="", CALCBULK(BC32), BA32*CALCBULK(BC32))) -> 0 | CC32: x | CD32: 0 | CE32: = | CF32: =IF(CD32="",0,IF(CB32="", CALCBULK(CD32), CB32*CALCBULK(CD32))) -> 0
I33: 0 | AE33: Bulk | BA33: Qty | BC33: Bulk | BE33: Total Bulk | CB33: Qty | CD33: Bulk | CF33: Total Bulk
BB34: x | BD34: = | BE34: =IF(BC34="",0,IF(BA34="", CALCBULK(BC34), BA34*CALCBULK(BC34))) -> 0 | CC34: x | CD34: 0 | CE34: = | CF34: =IF(CD34="",0,IF(CB34="", CALCBULK(CD34), CB34*CALCBULK(CD34))) -> 0
I35: 0 | AE35: Bulk | BA35: Qty | BC35: Bulk | BE35: Total Bulk | CB35: Qty | CD35: Bulk | CF35: Total Bulk
BB36: x | BD36: = | BE36: =IF(BC36="",0,IF(BA36="", CALCBULK(BC36), BA36*CALCBULK(BC36))) -> 0 | CC36: x | CD36: 0 | CE36: = | CF36: =IF(CD36="",0,IF(CB36="", CALCBULK(CD36), CB36*CALCBULK(CD36))) -> 0
I37: 0 | AE37: Bulk | BA37: Qty | BC37: Bulk | BE37: Total Bulk | CB37: Qty | CD37: Bulk | CF37: Total Bulk
BB38: x | BD38: = | BE38: =IF(BC38="",0,IF(BA38="", CALCBULK(BC38), BA38*CALCBULK(BC38))) -> 0 | CC38: x | CD38: 0 | CE38: = | CF38: =IF(CD38="",0,IF(CB38="", CALCBULK(CD38), CB38*CALCBULK(CD38))) -> 0
I39: 0 | AE39: Bulk | AG39: Bandolier (max. 8 items of light bulk) | BE39: Total Bulk | BH39: Special Container / Bag of Holding | CA39: Contribute Bulk? | CF39: Total Bulk
BE40: =SUM(BE42,BE44,BE46,BE48) -> 0 | CC40: 0 | CF40: =SUM(CF42:CF54) -> 0
I41: 0 | AE41: Bulk | BA41: Qty | BC41: Bulk | BE41: Total Bulk | CB41: Qty | CD41: Bulk | CF41: Total Bulk
BA42: 0 | BB42: x | BC42: L | BD42: = | BE42: =IF(BC42="",0,IF(BA42="", CALCBULK(BC42), BA42*CALCBULK(BC42))) -> 0 | CC42: x | CD42: 0 | CE42: = | CF42: =IF(CD42="",0,IF(CB42="", CALCBULK(CD42), CB42*CALCBULK(CD42))) -> 0
...

Sheet Spells
B2: CASTER LEVEL | V2: CANTRIPS | CO2: KNOWN SPELLS
B3: Level | F3: Caster Type: | S3: Cantrip | V3: Lv | X3: Lv+ | Z3: Actions | AC3: Name | AO3: Range | AR3: Target/Area | AY3: Save/Attack | BF3: Lv | BH3: Lv+ | BJ3: Actions | BM3: Name | BY3: Range | CB3: Target/Area | CI3: Save/Attack | CO3: Cantrips | DC3: 1st lv spells
B4: =Level -> 1 | F4: Druid | S4: =Roundup(Level/2,0) -> 1 | V4: =IF(AC4="","",$S$4) -> 1 | X4: =IF(AC4="","",VLOOKUP(AC4,'Spell Database'!$A$2:$W$1214,5,FALSE)) -> Y | Z4: =IF(AC4="","",VLOOKUP(AC4,'Spell Database'!$A$2:$W$1214,6,FALSE)) | AC4: Acid Splash | AO4: =IF(AC4="","",VLOOKUP(AC4,'Spell Database'!$A$2:$W$1214,8,FALSE)) -> 30ft | AR4: =IF(AC4="","",VLOOKUP(AC4,'Spell Database'!$A$2:$W$1214,9,FALSE)) -> 1 creature | AY4: =IF(AC4="","",VLOOKUP(AC4,'Spell Database'!$A$2:$W$1214,10,FALSE)) -> Attack | BF4: =IF(BM4="","",$S$4) | BH4: =IF(BM4="","",VLOOKUP(BM4,'Spell Database'!$A$2:$W$1214,5,FALSE)) | BJ4: =IF(BM4="","",VLOOKUP(BM4,'Spell Database'!$A$2:$W$1214,6,FALSE)) | BY4: =IF(BM4="","",VLOOKUP(BM4,'Spell Database'!$A$2:$W$1214,8,FALSE)) | CB4: =IF(BM4="","",VLOOKUP(BM4,'Spell Database'!$A$2:$W$1214,9,FALSE)) | CI4: =IF(BM4="","",VLOOKUP(BM4,'Spell Database'!$A$2:$W$1214,10,FALSE))
V5: Type | X5: Rarity | Z5: Component | AC5: =IF(AC4="","",VLOOKUP(AC4,'Spell Database'!$A$2:$V$1214, (IFs(V4=1,"13", V4=2,"14", V4=3,"15", V4=4,"16", V4=5,"17", V4=6,"18", V4=7,"19", V4=8,"20", V4=9,"21", V4=10,"22")),FALSE)) -> On hit deal 1d6 acid damage, plus 1 splash. On Crit target gains 1 persistent acid damage. | BF5: Type | BH5: Rarity | BJ5: Component | BM5: =IF(BM4="","",VLOOKUP(BM4,'Spell Database'!$A$2:$V$1214, (IFs(BF4=1,"13", BF4=2,"14", BF4=3,"15", BF4=4,"16", BF4=5,"17", BF4=6,"18", BF4=7,"19", BF4=8,"20", BF4=9,"21", BF4=10,"22")),FALSE))
B6: Level | F6: Max | H6: Used | V6: =IF(AC4="","",VLOOKUP(AC4,'Spell Database'!$A$2:$W$1214,12,FALSE)) -> C | X6: =IF(AC4="","",VLOOKUP(AC4,'Spell Database'!$A$2:$W$1214,3,FALSE)) -> C | Z6: =IF(AC4="","",VLOOKUP(AC4,'Spell Database'!$A$2:$W$1214,7,FALSE)) -> S,V | BF6: =IF(BM4="","",VLOOKUP(BM4,'Spell Database'!$A$2:$W$1214,12,FALSE)) | BH6: =IF(BM4="","",VLOOKUP(BM4,'Spell Database'!$A$2:$W$1214,3,FALSE)) | BJ6: =IF(BM4="","",VLOOKUP(BM4,'Spell Database'!$A$2:$W$1214,7,FALSE))
K7: Types of Casters | V7: Duration | Z7: School | BF7: Duration | BJ7: School | CO7: 2nd lv spells | DC7: 3rd lv spells
B8: Cantrip | F8: =IF(F4="",0, SWITCH(F4,"Magus",VLOOKUP(Level,Data!E27:P46,2), "Summoner",VLOOKUP(Level,Data!E27:P46,2), "Sorcerer",VLOOKUP(Level,Data!E50:P69,2), "Psychic",VLOOKUP(Level,Data!E73:DP92,2), "Basic Spellcaster",VLOOKUP(Level,Data!R27:AC46,2),"Expert Spellcaster",VLOOKUP(Level,Data!R50:AC69,2), "Master Spellcaster",VLOOKUP(Level,Data!R73:AC92,2),VLOOKUP(Level,Data!E4:P23,2))) -> 5 | H8: X | K8: Spontanious: Flexible Spell slots | V8: =IF(AC4="","",VLOOKUP(AC4,'Spell Database'!$A$2:$W$1214,11,FALSE)) -> Instant | Z8: =IF(AC4="","",VLOOKUP(AC4,'Spell Database'!$A$2:$W$1214,4,FALSE)) -> Evo | BF8: =IF(BM4="","",VLOOKUP(BM4,'Spell Database'!$A$2:$W$1214,11,FALSE)) | BJ8: =IF(BM4="","",VLOOKUP(BM4,'Spell Database'!$A$2:$W$1214,4,FALSE))
K9: Bards, Oracle, Sorcerers | V9: Lv | X9: Lv+ | Z9: Actions | AC9: Name | AO9: Range | AR9: Target/Area | AY9: Save/Attack | BF9: Lv | BH9: Lv+ | BJ9: Actions | BM9: Name | BY9: Range | CB9: Target/Area | CI9: Save/Attack
B10: Focus | F10: 0 | H10: 0 | K10: Every spell you learn becomes an option to cast, but can only be changed out when you level up. Any spell can be cast by expending the spellslot, no preperation required. Cant overcast easily. | V10: =IF(AC10="","",$S$4) | X10: =IF(AC10="","",VLOOKUP(AC10,'Spell Database'!$A$2:$W$1214,5,FALSE)) | Z10: =IF(AC10="","",VLOOKUP(AC10,'Spell Database'!$A$2:$W$1214,6,FALSE)) | AO10: =IF(AC10="","",VLOOKUP(AC10,'Spell Database'!$A$2:$W$1214,8,FALSE)) | AR10: =IF(AC10="","",VLOOKUP(AC10,'Spell Database'!$A$2:$W$1214,9,FALSE)) | AY10: =IF(AC10="","",VLOOKUP(AC10,'Spell Database'!$A$2:$W$1214,10,FALSE)) | BF10: =IF(BM10="","",$S$4) | BH10: =IF(BM10="","",VLOOKUP(BM10,'Spell Database'!$A$2:$W$1214,5,FALSE)) | BJ10: =IF(BM10="","",VLOOKUP(BM10,'Spell Database'!$A$2:$W$1214,6,FALSE)) | BY10: =IF(BM10="","",VLOOKUP(BM10,'Spell Database'!$A$2:$W$1214,8,FALSE)) | CB10: =IF(BM10="","",VLOOKUP(BM10,'Spell Database'!$A$2:$W$1214,9,FALSE)) | CI10: =IF(BM10="","",VLOOKUP(BM10,'Spell Database'!$A$2:$W$1214,10,FALSE))
V11: Type | X11: Rarity | Z11: Component | AC11: =IF(AC10="","",VLOOKUP(AC10,'Spell Database'!$A$2:$V$1214, (IFs(V10=1,"13", V10=2,"14", V10=3,"15", V10=4,"16", V10=5,"17", V10=6,"18", V10=7,"19", V10=8,"20", V10=9,"21", V10=10,"22")),FALSE)) | BF11: Type | BH11: Rarity | BJ11: Component | BM11: =IF(BM10="","",VLOOKUP(BM10,'Spell Database'!$A$2:$V$1214, (IFs(BF10=1,"13", BF10=2,"14", BF10=3,"15", BF10=4,"16", BF10=5,"17", BF10=6,"18", BF10=7,"19", BF10=8,"20", BF10=9,"21", BF10=10,"22")),FALSE)) | CO11: 4th lv spells | DC11: 5th lv spells
B12: 1st Lv | F12: =IF(F4="",0, SWITCH(F4,"Magus",VLOOKUP(Level,Data!E27:P46,3), "Summoner",VLOOKUP(Level,Data!E27:P46,3), "Sorcerer",VLOOKUP(Level,Data!E50:P69,3), "Psychic",VLOOKUP(Level,Data!E73:DP92,3), "Basic Spellcaster",VLOOKUP(Level,Data!R27:AC46,3),"Expert Spellcaster",VLOOKUP(Level,Data!R50:AC69,3), "Master Spellcaster",VLOOKUP(Level,Data!R73:AC92,3),VLOOKUP(Level,Data!E4:P23,3))) -> 2 | H12: =Sum(AK40,AK46,AK52,BX40,BX46,BX52) -> 0 | V12: =IF(AC10="","",VLOOKUP(AC10,'Spell Database'!$A$2:$W$1214,12,FALSE)) | X12: =IF(AC10="","",VLOOKUP(AC10,'Spell Database'!$A$2:$W$1214,3,FALSE)) | Z12: =IF(AC10="","",VLOOKUP(AC10,'Spell Database'!$A$2:$W$1214,7,FALSE)) | BF12: =IF(BM10="","",VLOOKUP(BM10,'Spell Database'!$A$2:$W$1214,12,FALSE)) | BH12: =IF(BM10="","",VLOOKUP(BM10,'Spell Database'!$A$2:$W$1214,3,FALSE)) | BJ12: =IF(BM10="","",VLOOKUP(BM10,'Spell Database'!$A$2:$W$1214,7,FALSE))
V13: Duration | Z13: School | BF13: Duration | BJ13: School
B14: 2nd Lv | F14: =IF(F4="",0, SWITCH(F4,"Magus",VLOOKUP(Level,Data!E27:P46,4), "Summoner",VLOOKUP(Level,Data!E27:P46,4), "Sorcerer",VLOOKUP(Level,Data!E50:P69,4), "Psychic",VLOOKUP(Level,Data!E73:DP92,4), "Basic Spellcaster",VLOOKUP(Level,Data!R27:AC46,4),"Expert Spellcaster",VLOOKUP(Level,Data!R50:AC69,4), "Master Spellcaster",VLOOKUP(Level,Data!R73:AC92,4),VLOOKUP(Level,Data!E4:P23,4))) -> 0 | H14: =SUM(AK60,AK66,AK72,BX60,BX66,BX72) -> 0 | V14: =IF(AC10="","",VLOOKUP(AC10,'Spell Database'!$A$2:$W$1214,11,FALSE)) | Z14: =IF(AC10="","",VLOOKUP(AC10,'Spell Database'!$A$2:$W$1214,4,FALSE)) | BF14: =IF(BM10="","",VLOOKUP(BM10,'Spell Database'!$A$2:$W$1214,11,FALSE)) | BJ14: =IF(BM10="","",VLOOKUP(BM10,'Spell Database'!$A$2:$W$1214,4,FALSE))
V15: Lv | X15: Lv+ | Z15: Actions | AC15: Name | AO15: Range | AR15: Target/Area | AY15: Save/Attack | BF15: Lv | BH15: Lv+ | BJ15: Actions | BM15: Name | BY15: Range | CB15: Target/Area | CI15: Save/Attack | CO15: 6th lv spells | DC15: 7th lv spells
B16: 3rd Lv | F16: =IF(F4="",0, SWITCH(F4,"Magus",VLOOKUP(Level,Data!E27:P46,5), "Summoner",VLOOKUP(Level,Data!E27:P46,5), "Sorcerer",VLOOKUP(Level,Data!E50:P69,5), "Psychic",VLOOKUP(Level,Data!E73:DP92,5), "Basic Spellcaster",VLOOKUP(Level,Data!R27:AC46,5),"Expert Spellcaster",VLOOKUP(Level,Data!R50:AC69,5), "Master Spellcaster",VLOOKUP(Level,Data!R73:AC92,5),VLOOKUP(Level,Data!E4:P23,5))) -> 0 | H16: =SUM(AK80,AK86,BX80,BX86) -> 0 | K16: Prepared: Flexible Spell knowledge | V16: =IF(AC16="","",$S$4) | X16: =IF(AC16="","",VLOOKUP(AC16,'Spell Database'!$A$2:$W$1214,5,FALSE)) | Z16: =IF(AC16="","",VLOOKUP(AC16,'Spell Database'!$A$2:$W$1214,6,FALSE)) | AO16: =IF(AC16="","",VLOOKUP(AC16,'Spell Database'!$A$2:$W$1214,8,FALSE)) | AR16: =IF(AC16="","",VLOOKUP(AC16,'Spell Database'!$A$2:$W$1214,9,FALSE)) | AY16: =IF(AC16="","",VLOOKUP(AC16,'Spell Database'!$A$2:$W$1214,10,FALSE)) | BF16: =IF(BM16="","",$S$4) | BH16: =IF(BM16="","",VLOOKUP(BM16,'Spell Database'!$A$2:$W$1214,5,FALSE)) | BJ16: =IF(BM16="","",VLOOKUP(BM16,'Spell Database'!$A$2:$W$1214,6,FALSE)) | BY16: =IF(BM16="","",VLOOKUP(BM16,'Spell Database'!$A$2:$W$1214,8,FALSE)) | CB16: =IF(BM16="","",VLOOKUP(BM16,'Spell Database'!$A$2:$W$1214,9,FALSE)) | CI16: =IF(BM16="","",VLOOKUP(BM16,'Spell Database'!$A$2:$W$1214,10,FALSE))
K17: Cleric, druid, wizard | V17: Type | X17: Rarity | Z17: Component | AC17: =IF(AC16="","",VLOOKUP(AC16,'Spell Database'!$A$2:$V$1214, (IFs(V16=1,"13", V16=2,"14", V16=3,"15", V16=4,"16", V16=5,"17", V16=6,"18", V16=7,"19", V16=8,"20", V16=9,"21", V16=10,"22")),FALSE)) | BF17: Type | BH17: Rarity | BJ17: Component | BM17: =IF(BM16="","",VLOOKUP(BM16,'Spell Database'!$A$2:$V$1214, (IFs(BF16=1,"13", BF16=2,"14", BF16=3,"15", BF16=4,"16", BF16=5,"17", BF16=6,"18", BF16=7,"19", BF16=8,"20", BF16=9,"21", BF16=10,"22")),FALSE))
B18: 4th Lv | F18: =IF(F4="",0, SWITCH(F4,"Magus",VLOOKUP(Level,Data!E27:P46,6), "Summoner",VLOOKUP(Level,Data!E27:P46,6), "Sorcerer",VLOOKUP(Level,Data!E50:P69,6), "Psychic",VLOOKUP(Level,Data!E73:DP92,6), "Basic Spellcaster",VLOOKUP(Level,Data!R27:AC46,6),"Expert Spellcaster",VLOOKUP(Level,Data!R50:AC69,6), "Master Spellcaster",VLOOKUP(Level,Data!R73:AC92,6),VLOOKUP(Level,Data!E4:P23,6))) -> 0 | H18: =SUM(AK94,AK100,BX94,BX100) -> 0 | K18: Every morning you prepare the spells you wish to cast that day, and the level you want to cast them at. You can only cast a spell as many times as you prepare it. | V18: =IF(AC16="","",VLOOKUP(AC16,'Spell Database'!$A$2:$W$1214,12,FALSE)) | X18: =IF(AC16="","",VLOOKUP(AC16,'Spell Database'!$A$2:$W$1214,3,FALSE)) | Z18: =IF(AC16="","",VLOOKUP(AC16,'Spell Database'!$A$2:$W$1214,7,FALSE)) | BF18: =IF(BM16="","",VLOOKUP(BM16,'Spell Database'!$A$2:$W$1214,12,FALSE)) | BH18: =IF(BM16="","",VLOOKUP(BM16,'Spell Database'!$A$2:$W$1214,3,FALSE)) | BJ18: =IF(BM16="","",VLOOKUP(BM16,'Spell Database'!$A$2:$W$1214,7,FALSE))
V19: Duration | Z19: School | BF19: Duration | BJ19: School | CO19: 8th lv spells | DC19: 9th lv spells
B20: 5th Lv | F20: =IF(F4="",0, SWITCH(F4,"Magus",VLOOKUP(Level,Data!E27:P46,7), "Summoner",VLOOKUP(Level,Data!E27:P46,7), "Sorcerer",VLOOKUP(Level,Data!E50:P69,7), "Psychic",VLOOKUP(Level,Data!E73:DP92,7), "Basic Spellcaster",VLOOKUP(Level,Data!R27:AC46,7),"Expert Spellcaster",VLOOKUP(Level,Data!R50:AC69,7), "Master Spellcaster",VLOOKUP(Level,Data!R73:AC92,7),VLOOKUP(Level,Data!E4:P23,7))) -> 0 | H20: =SUM(AK108,AK114,BX108,BX114,) -> 0 | V20: =IF(AC16="","",VLOOKUP(AC16,'Spell Database'!$A$2:$W$1214,11,FALSE)) | Z20: =IF(AC16="","",VLOOKUP(AC16,'Spell Database'!$A$2:$W$1214,4,FALSE)) | BF20: =IF(BM16="","",VLOOKUP(BM16,'Spell Database'!$A$2:$W$1214,11,FALSE)) | BJ20: =IF(BM16="","",VLOOKUP(BM16,'Spell Database'!$A$2:$W$1214,4,FALSE))
B22: 6th Lv | F22: =IF(F4="",0, SWITCH(F4,"Magus",VLOOKUP(Level,Data!E27:P46,8), "Summoner",VLOOKUP(Level,Data!E27:P46,8), "Sorcerer",VLOOKUP(Level,Data!E50:P69,8), "Psychic",VLOOKUP(Level,Data!E73:DP92,8), "Basic Spellcaster",VLOOKUP(Level,Data!R27:AC46,8),"Expert Spellcaster",VLOOKUP(Level,Data!R50:AC69,8), "Master Spellcaster",VLOOKUP(Level,Data!R73:AC92,8),VLOOKUP(Level,Data!E4:P23,8))) -> 0 | H22: =SUM(AK122,AK128,BX122,BX128) -> 0 | V22: FOCUS SPELLS AND EXTRA CANTRIPS
V23: Lv | X23: Lv+ | Z23: Actions | AC23: Name | AO23: Range | AR23: Target/Area | AY23: Save/Attack | BF23: Lv | BH23: Lv+ | BJ23: Actions | BM23: Name | BY23: Range | CB23: Target/Area | CI23: Save/Attack | CO23: Anything of Note: | DC23: Fill in your own desired content:
B24: 7th Lv | F24: =IF(F4="",0, SWITCH(F4,"Magus",VLOOKUP(Level,Data!E27:P46,9), "Summoner",VLOOKUP(Level,Data!E27:P46,9), "Sorcerer",VLOOKUP(Level,Data!E50:P69,9), "Psychic",VLOOKUP(Level,Data!E73:DP92,9), "Basic Spellcaster",VLOOKUP(Level,Data!R27:AC46,9),"Expert Spellcaster",VLOOKUP(Level,Data!R50:AC69,9), "Master Spellcaster",VLOOKUP(Level,Data!R73:AC92,9),VLOOKUP(Level,Data!E4:P23,9))) -> 0 | H24: =SUM(AK136,AK142,BX136,BX142) -> 0 | V24: =IF(AC24="","",$S$4) | X24: =IF(AC24="","",VLOOKUP(AC24,'Spell Database'!$A$2:$W$1214,5,FALSE)) | Z24: =IF(AC24="","",VLOOKUP(AC24,'Spell Database'!$A$2:$W$1214,6,FALSE)) | AO24: =IF(AC24="","",VLOOKUP(AC24,'Spell Database'!$A$2:$W$1214,8,FALSE)) | AR24: =IF(AC24="","",VLOOKUP(AC24,'Spell Database'!$A$2:$W$1214,9,FALSE)) | AY24: =IF(AC24="","",VLOOKUP(AC24,'Spell Database'!$A$2:$W$1214,10,FALSE)) | BF24: =IF(BM24="","",$S$4) | BH24: =IF(BM24="","",VLOOKUP(BM24,'Spell Database'!$A$2:$W$1214,5,FALSE)) | BJ24: =IF(BM24="","",VLOOKUP(BM24,'Spell Database'!$A$2:$W$1214,6,FALSE)) | BY24: =IF(BM24="","",VLOOKUP(BM24,'Spell Database'!$A$2:$W$1214,8,FALSE)) | CB24: =IF(BM24="","",VLOOKUP(BM24,'Spell Database'!$A$2:$W$1214,9,FALSE)) | CI24: =IF(BM24="","",VLOOKUP(BM24,'Spell Database'!$A$2:$W$1214,10,FALSE))
V25: Type | X25: Rarity | Z25: Component | AC25: =IF(AC24="","",VLOOKUP(AC24,'Spell Database'!$A$2:$V$1214, (IFs(V24=1,"13", V24=2,"14", V24=3,"15", V24=4,"16", V24=5,"17", V24=6,"18", V24=7,"19", V24=8,"20", V24=9,"21", V24=10,"22")),FALSE)) | BF25: Type | BH25: Rarity | BJ25: Component | BM25: =IF(BM24="","",VLOOKUP(BM24,'Spell Database'!$A$2:$V$1214, (IFs(BF24=1,"13", BF24=2,"14", BF24=3,"15", BF24=4,"16", BF24=5,"17", BF24=6,"18", BF24=7,"19", BF24=8,"20", BF24=9,"21", BF24=10,"22")),FALSE))
B26: 8th Lv | F26: =IF(F4="",0, SWITCH(F4,"Magus",VLOOKUP(Level,Data!E27:P46,10), "Summoner",VLOOKUP(Level,Data!E27:P46,10), "Sorcerer",VLOOKUP(Level,Data!E50:P69,10), "Psychic",VLOOKUP(Level,Data!E73:DP92,10), "Basic Spellcaster",VLOOKUP(Level,Data!R27:AC46,10),"Expert Spellcaster",VLOOKUP(Level,Data!R50:AC69,10), "Master Spellcaster",VLOOKUP(Level,Data!R73:AC92,10),VLOOKUP(Level,Data!E4:P23,10))) -> 0 | H26: =SUM(AK150,AK156,BX150,BX156) -> 0 | V26: =IF(AC24="","",VLOOKUP(AC24,'Spell Database'!$A$2:$W$1214,12,FALSE)) | X26: =IF(AC24="","",VLOOKUP(AC24,'Spell Database'!$A$2:$W$1214,3,FALSE)) | Z26: =IF(AC24="","",VLOOKUP(AC24,'Spell Database'!$A$2:$W$1214,7,FALSE)) | BF26: =IF(BM24="","",VLOOKUP(BM24,'Spell Database'!$A$2:$W$1214,12,FALSE)) | BH26: =IF(BM24="","",VLOOKUP(BM24,'Spell Database'!$A$2:$W$1214,3,FALSE)) | BJ26: =IF(BM24="","",VLOOKUP(BM24,'Spell Database'!$A$2:$W$1214,7,FALSE))
V27: Duration | Z27: School | BF27: Duration | BJ27: School
B28: 9th Lv | F28: =IF(F4="",0, SWITCH(F4,"Magus",VLOOKUP(Level,Data!E27:P46,11), "Summoner",VLOOKUP(Level,Data!E27:P46,11), "Sorcerer",VLOOKUP(Level,Data!E50:P69,11), "Psychic",VLOOKUP(Level,Data!E73:DP92,11), "Basic Spellcaster",VLOOKUP(Level,Data!R27:AC46,11),"Expert Spellcaster",VLOOKUP(Level,Data!R50:AC69,11), "Master Spellcaster",VLOOKUP(Level,Data!R73:AC92,11),VLOOKUP(Level,Data!E4:P23,11))) -> 0 | H28: =SUM(AK164,AK170,BX164,BX170) -> 0 | V28: =IF(AC24="","",VLOOKUP(AC24,'Spell Database'!$A$2:$W$1214,11,FALSE)) | Z28: =IF(AC24="","",VLOOKUP(AC24,'Spell Database'!$A$2:$W$1214,4,FALSE)) | BF28: =IF(BM24="","",VLOOKUP(BM24,'Spell Database'!$A$2:$W$1214,11,FALSE)) | BJ28: =IF(BM24="","",VLOOKUP(BM24,'Spell Database'!$A$2:$W$1214,4,FALSE))
V29: Lv | X29: Lv+ | Z29: Actions | AC29: Name | AO29: Range | AR29: Target/Area | AY29: Save/Attack | BF29: Lv | BH29: Lv+ | BJ29: Actions | BM29: Name | BY29: Range | CB29: Target/Area | CI29: Save/Attack | CO29: Other Notes:
B30: 10th Lv | F30: =IF(F4="",0, SWITCH(F4,"Magus",VLOOKUP(Level,Data!E27:P46,12), "Summoner",VLOOKUP(Level,Data!E27:P46,12), "Sorcerer",VLOOKUP(Level,Data!E50:P69,12), "Psychic",VLOOKUP(Level,Data!E73:DP92,12), "Basic Spellcaster",VLOOKUP(Level,Data!R27:AC46,12),"Expert Spellcaster",VLOOKUP(Level,Data!R50:AC69,12), "Master Spellcaster",VLOOKUP(Level,Data!R73:AC92,12),VLOOKUP(Level,Data!E4:P23,12))) -> 0 | H30: =SUM(AK178,BX178) -> 0 | V30: =IF(AC30="","",$S$4) | X30: =IF(AC30="","",VLOOKUP(AC30,'Spell Database'!$A$2:$W$1214,5,FALSE)) | Z30: =IF(AC30="","",VLOOKUP(AC30,'Spell Database'!$A$2:$W$1214,6,FALSE)) | AO30: =IF(AC30="","",VLOOKUP(AC30,'Spell Database'!$A$2:$W$1214,8,FALSE)) | AR30: =IF(AC30="","",VLOOKUP(AC30,'Spell Database'!$A$2:$W$1214,9,FALSE)) | AY30: =IF(AC30="","",VLOOKUP(AC30,'Spell Database'!$A$2:$W$1214,10,FALSE)) | BF30: =IF(BM30="","",$S$4) | BH30: =IF(BM30="","",VLOOKUP(BM30,'Spell Database'!$A$2:$W$1214,5,FALSE)) | BJ30: =IF(BM30="","",VLOOKUP(BM30,'Spell Database'!$A$2:$W$1214,6,FALSE)) | BY30: =IF(BM30="","",VLOOKUP(BM30,'Spell Database'!$A$2:$W$1214,8,FALSE)) | CB30: =IF(BM30="","",VLOOKUP(BM30,'Spell Database'!$A$2:$W$1214,9,FALSE)) | CI30: =IF(BM30="","",VLOOKUP(BM30,'Spell Database'!$A$2:$W$1214,10,FALSE))
V31: Type | X31: Rarity | Z31: Component | AC31: =IF(AC30="","",VLOOKUP(AC30,'Spell Database'!$A$2:$V$1214, (IFs(V30=1,"13", V30=2,"14", V30=3,"15", V30=4,"16", V30=5,"17", V30=6,"18", V30=7,"19", V30=8,"20", V30=9,"21", V30=10,"22")),FALSE)) | BF31: Type | BH31: Rarity | BJ31: Component | BM31: =IF(BM30="","",VLOOKUP(BM30,'Spell Database'!$A$2:$V$1214, (IFs(BF30=1,"13", BF30=2,"14", BF30=3,"15", BF30=4,"16", BF30=5,"17", BF30=6,"18", BF30=7,"19", BF30=8,"20", BF30=9,"21", BF30=10,"22")),FALSE))
V32: =IF(AC30="","",VLOOKUP(AC30,'Spell Database'!$A$2:$W$1214,12,FALSE)) | X32: =IF(AC30="","",VLOOKUP(AC30,'Spell Database'!$A$2:$W$1214,3,FALSE)) | Z32: =IF(AC30="","",VLOOKUP(AC30,'Spell Database'!$A$2:$W$1214,7,FALSE)) | BF32: =IF(BM30="","",VLOOKUP(BM30,'Spell Database'!$A$2:$W$1214,12,FALSE)) | BH32: =IF(BM30="","",VLOOKUP(BM30,'Spell Database'!$A$2:$W$1214,3,FALSE)) | BJ32: =IF(BM30="","",VLOOKUP(BM30,'Spell Database'!$A$2:$W$1214,7,FALSE))
D33: Long Rest | H33: FALSE | V33: Duration | Z33: School | BF33: Duration | BJ33: School
V34: =IF(AC30="","",VLOOKUP(AC30,'Spell Database'!$A$2:$W$1214,11,FALSE)) | Z34: =IF(AC30="","",VLOOKUP(AC30,'Spell Database'!$A$2:$W$1214,4,FALSE)) | BF34: =IF(BM30="","",VLOOKUP(BM30,'Spell Database'!$A$2:$W$1214,11,FALSE)) | BJ34: =IF(BM30="","",VLOOKUP(BM30,'Spell Database'!$A$2:$W$1214,4,FALSE))
H35: =IF(H33,true,"")
B36: 1st LEVEL SPELLS | CB36: MAGIC ITEM SPELLS
B37: Lv | D37: Lv+ | F37: Actions | I37: Name | U37: Range | X37: Target/Area | AE37: Save/Attack | AK37: Prepared | AO37: Lv | AQ37: Lv+ | AS37: Actions | AV37: Name | BH37: Range | BK37: Target/Area | BR37: Save/Attack | BX37: Prepared | CB37: Lv | CD37: Lv+ | CF37: Actions | CI37: Name | CS37: Range | CV37: Target/Area | DC37: Save/Attack | DH37: Item DC | DK37: Uses | DN37: Used
B38: =IF(I38="","",VLOOKUP(I38,'Spell Database'!$A$2:$W$1214,2,FALSE)) -> 1 | D38: =IF(I38="","",VLOOKUP(I38,'Spell Database'!$A$2:$W$1214,5,FALSE)) -> Y | F38: =IF(I38="","",VLOOKUP(I38,'Spell Database'!$A$2:$W$1214,6,FALSE)) | I38: Animate Dead | U38: =IF(I38="","",VLOOKUP(I38,'Spell Database'!$A$2:$W$1214,8,FALSE)) -> 30ft | X38: =IF(I38="","",VLOOKUP(I38,'Spell Database'!$A$2:$W$1214,9,FALSE)) -> N/A | AE38: =IF(I38="","",VLOOKUP(I38,'Spell Database'!$A$2:$W$1214,10,FALSE)) -> N/A | AO38: =IF(AV38="","",VLOOKUP(AV38,'Spell Database'!$A$2:$W$1214,2,FALSE)) | AQ38: =IF(AV38="","",VLOOKUP(AV38,'Spell Database'!$A$2:$W$1214,5,FALSE)) | AS38: =IF(AV38="","",VLOOKUP(AV38,'Spell Database'!$A$2:$W$1214,6,FALSE)) | BH38: =IF(AV38="","",VLOOKUP(AV38,'Spell Database'!$A$2:$W$1214,8,FALSE)) | BK38: =IF(AV38="","",VLOOKUP(AV38,'Spell Database'!$A$2:$W$1214,9,FALSE)) | BR38: =IF(AV38="","",VLOOKUP(AV38,'Spell Database'!$A$2:$W$1214,10,FALSE)) | CB38: =IF(CI38="","",VLOOKUP(CI38,'Spell Database'!$A$2:$W$1214,2,FALSE)) | CD38: =IF(CI38="","",VLOOKUP(CI38,'Spell Database'!$A$2:$W$1214,5,FALSE)) | CF38: =IF(CI38="","",VLOOKUP(CI38,'Spell Database'!$A$2:$W$1214,6,FALSE)) | CS38: =IF(CI38="","",VLOOKUP(CI38,'Spell Database'!$A$2:$W$1214,8,FALSE)) | CV38: =IF(CI38="","",VLOOKUP(CI38,'Spell Database'!$A$2:$W$1214,9,FALSE)) | DC38: =IF(CI38="","",VLOOKUP(CI38,'Spell Database'!$A$2:$W$1214,10,FALSE))
B39: Type | D39: Rarity | F39: Component | I39: =IF(I38="","",VLOOKUP(I38,'Spell Database'!$A$2:$V$1214, (IFs(B38=1,"13", B38=2,"14", B38=3,"15", B38=4,"16", B38=5,"17", B38=6,"18", B38=7,"19", B38=8,"20", B38=9,"21", B38=10,"22")),FALSE)) -> You magically summon a corpse or skeleton filled with necromatic life. You summon an creature whose level is -1 with the undead trait. This creature gains the summoned trait. | AK39: Used | AO39: Type | AQ39: Rarity | AS39: Component | AV39: =IF(AV38="","",VLOOKUP(AV38,'Spell Database'!$A$2:$V$1214, (IFs(AO38=1,"13", AO38=2,"14", AO38=3,"15", AO38=4,"16", AO38=5,"17", AO38=6,"18", AO38=7,"19", AO38=8,"20", AO38=9,"21", AO38=10,"22")),FALSE)) | BX39: Used | CB39: Type | CD39: Rarity | CF39: Component | CI39: =IF(CI38="","",VLOOKUP(CI38,'Spell Database'!$A$2:$V$1214, (IFs(CB38=1,"13", CB38=2,"14", CB38=3,"15", CB38=4,"16", CB38=5,"17", CB38=6,"18", CB38=7,"19", CB38=8,"20", CB38=9,"21", CB38=10,"22")),FALSE)) | DK39: Source
B40: =IF(I38="","",VLOOKUP(I38,'Spell Database'!$A$2:$W$1214,12,FALSE)) -> S | D40: =IF(I38="","",VLOOKUP(I38,'Spell Database'!$A$2:$W$1214,3,FALSE)) -> C | F40: =IF(I38="","",VLOOKUP(I38,'Spell Database'!$A$2:$W$1214,7,FALSE)) -> M,S,V | AK40: 0 | AO40: =IF(AV38="","",VLOOKUP(AV38,'Spell Database'!$A$2:$W$1214,12,FALSE)) | AQ40: =IF(AV38="","",VLOOKUP(AV38,'Spell Database'!$A$2:$W$1214,3,FALSE)) | AS40: =IF(AV38="","",VLOOKUP(AV38,'Spell Database'!$A$2:$W$1214,7,FALSE)) | BX40: 0 | CB40: =IF(CI38="","",VLOOKUP(CI38,'Spell Database'!$A$2:$W$1214,12,FALSE)) | CD40: =IF(CI38="","",VLOOKUP(CI38,'Spell Database'!$A$2:$W$1214,3,FALSE)) | CF40: =IF(CI38="","",VLOOKUP(CI38,'Spell Database'!$A$2:$W$1214,7,FALSE))
B41: Duration | F41: School | AO41: Duration | AS41: School | CB41: Duration | CF41: School
B42: =IF(I38="","",VLOOKUP(I38,'Spell Database'!$A$2:$W$1214,11,FALSE)) -> [S] 1min | F42: =IF(I38="","",VLOOKUP(I38,'Spell Database'!$A$2:$W$1214,4,FALSE)) -> Nec | AO42: =IF(AV38="","",VLOOKUP(AV38,'Spell Database'!$A$2:$W$1214,11,FALSE)) | AS42: =IF(AV38="","",VLOOKUP(AV38,'Spell Database'!$A$2:$W$1214,4,FALSE)) | CB42: =IF(CI38="","",VLOOKUP(CI38,'Spell Database'!$A$2:$W$1214,11,FALSE)) | CF42: =IF(CI38="","",VLOOKUP(CI38,'Spell Database'!$A$2:$W$1214,4,FALSE))
...

Sheet Spell Database
A1: name | B1: level | C1: rarity | D1: school | E1: heightenable | F1: actions | G1: components | H1: Range | I1: Target | J1: Saving Throw | K1: Duration | L1: category | M1: Level 1 | N1: Level 2 | O1: Level 3 | P1: Level 4 | Q1: Level 5 | R1: Level 6 | S1: Level 7 | T1: Level 8 | U1: Level 9 | V1: Level 10 | W1: traditions | X1: Source
A2: Acid Splash | B2: =Spells!$S$4 -> 1 | C2: C | D2: Evo | E2: Y | F2: ='Character Sheet'!$C$9 | G2: S,V | H2: 30ft | I2: 1 creature | J2: Attack | K2: Instant | L2: C | M2: On hit deal 1d6 acid damage, plus 1 splash. On Crit target gains 1 persistent acid damage. | N2: On hit deal 1d6 acid damage, plus 1 splash. On Crit target gains 1 persistent acid damage. | O2: On hit deal 1d6+[Spellcasting Mod] acid damage, plus 1 splash. On Crit target gains 2 persistent acid damage. | P2: On hit deal 1d6+[Spellcasting Mod] acid damage, plus 1 splash. On Crit target gains 2 persistent acid damage. | Q2: On hit deal 2d6+[Spellcasting Mod] acid damage, plus 2 splash damage. On Crit target gains 3 persistent acid damage. | R2: On hit deal 2d6+[Spellcasting Mod] acid damage, plus 2 splash damage. On Crit target gains 3 persistent acid damage. | S2: On hit deal 3d6+[Spellcasting Mod] acid damage, plus 3 splash damage. On Crit target gains 4 persistent acid damage. | T2: On hit deal 3d6+[Spellcasting Mod] acid damage, plus 3 splash damage. On Crit target gains 4 persistent acid damage. | U2: On hit deal 4d6+[Spellcasting Mod] acid damage, plus 4 splash damage. On Crit target gains 5 persistent acid damage. | V2: On hit deal 4d6+[Spellcasting Mod] acid damage, plus 4 splash damage. On Crit target gains 5 persistent acid damage. | W2: arcane, primal | X2: Core
A3: Approximate | B3: =Spells!$S$4 -> 1 | C3: C | D3: Div | E3: N | F3: ='Character Sheet'!$C$9 | G3: S,V | H3: 10ft | I3: 1ft cube | J3: N/A | K3: Instant | L3: C | M3: Name object to count; instantly gain rounded number of objects you can see. Rounds to the largest number (180 copper becomes 200). Note: "Dented copper coins" is different than "copper coins" and gold plated coins will show up as "gold coins" | N3: Name object to count; instantly gain rounded number of objects you can see. Rounds to the largest number (180 copper becomes 200). Note: "Dented copper coins" is different than "copper coins" and gold plated coins will show up as "gold coins" | O3: Name object to count; instantly gain rounded number of objects you can see. Rounds to the largest number (180 copper becomes 200). Note: "Dented copper coins" is different than "copper coins" and gold plated coins will show up as "gold coins" | P3: Name object to count; instantly gain rounded number of objects you can see. Rounds to the largest number (180 copper becomes 200). Note: "Dented copper coins" is different than "copper coins" and gold plated coins will show up as "gold coins" | Q3: Name object to count; instantly gain rounded number of objects you can see. Rounds to the largest number (180 copper becomes 200). Note: "Dented copper coins" is different than "copper coins" and gold plated coins will show up as "gold coins" | R3: Name object to count; instantly gain rounded number of objects you can see. Rounds to the largest number (180 copper becomes 200). Note: "Dented copper coins" is different than "copper coins" and gold plated coins will show up as "gold coins" | S3: Name object to count; instantly gain rounded number of objects you can see. Rounds to the largest number (180 copper becomes 200). Note: "Dented copper coins" is different than "copper coins" and gold plated coins will show up as "gold coins" | T3: Name object to count; instantly gain rounded number of objects you can see. Rounds to the largest number (180 copper becomes 200). Note: "Dented copper coins" is different than "copper coins" and gold plated coins will show up as "gold coins" | U3: Name object to count; instantly gain rounded number of objects you can see. Rounds to the largest number (180 copper becomes 200). Note: "Dented copper coins" is different than "copper coins" and gold plated coins will show up as "gold coins" | V3: Name object to count; instantly gain rounded number of objects you can see. Rounds to the largest number (180 copper becomes 200). Note: "Dented copper coins" is different than "copper coins" and gold plated coins will show up as "gold coins" | W3: arcane, divine, occult, primal | X3: Secrets of Magic
